Workbook

Sheet ダッシュボード
A2: ダンジョンゲーム 制作TODOダッシュボード
A3: 基準期間：2026-09-18〜2027-03-18 個人制作・Windows PC・Visual Studio 2026 / C++
A5: 指標 | B5: 値 | D5: フェーズ | E5: TODO数 | F5: 完了数 | G5: 進捗
A6: 総TODO数 | B6: =COUNTA(TODO一覧!$A$6:$A$492) -> 487 | D6: F0 企画固定 | E6: =COUNTIF(TODO一覧!$B$6:$B$492,D6) -> 30 | F6: =COUNTIFS(TODO一覧!$B$6:$B$492,D6,TODO一覧!$H$6:$H$492,"完了") -> 7 | G6: =IF(E6=0,0,F6/E6) -> 0.23333333
A7: 完了数 | B7: =COUNTIF(TODO一覧!$H$6:$H$492,"完了") -> 7 | D7: F1 基礎 | E7: =COUNTIF(TODO一覧!$B$6:$B$492,D7) -> 42 | F7: =COUNTIFS(TODO一覧!$B$6:$B$492,D7,TODO一覧!$H$6:$H$492,"完了") -> 0 | G7: =IF(E7=0,0,F7/E7) -> 0
A8: 進行中 | B8: =COUNTIF(TODO一覧!$H$6:$H$492,"進行中") -> 0 | D8: F2 戦闘試作 | E8: =COUNTIF(TODO一覧!$B$6:$B$492,D8) -> 57 | F8: =COUNTIFS(TODO一覧!$B$6:$B$492,D8,TODO一覧!$H$6:$H$492,"完了") -> 0 | G8: =IF(E8=0,0,F8/E8) -> 0
A9: 確認待ち | B9: =COUNTIF(TODO一覧!$H$6:$H$492,"確認待ち") -> 15 | D9: F3 ケース | E9: =COUNTIF(TODO一覧!$B$6:$B$492,D9) -> 30 | F9: =COUNTIFS(TODO一覧!$B$6:$B$492,D9,TODO一覧!$H$6:$H$492,"完了") -> 0 | G9: =IF(E9=0,0,F9/E9) -> 0
A10: 全体進捗 | B10: =SUMPRODUCT(TODO一覧!$M$6:$M$492,TODO一覧!$O$6:$O$492)/SUM(TODO一覧!$M$6:$M$492) -> 0.0028892456 | D10: F4 ループ統合 | E10: =COUNTIF(TODO一覧!$B$6:$B$492,D10) -> 55 | F10: =COUNTIFS(TODO一覧!$B$6:$B$492,D10,TODO一覧!$H$6:$H$492,"完了") -> 0 | G10: =IF(E10=0,0,F10/E10) -> 0
D11: F5 縦切り | E11: =COUNTIF(TODO一覧!$B$6:$B$492,D11) -> 57 | F11: =COUNTIFS(TODO一覧!$B$6:$B$492,D11,TODO一覧!$H$6:$H$492,"完了") -> 0 | G11: =IF(E11=0,0,F11/E11) -> 0
D12: F6 キャンペーン | E12: =COUNTIF(TODO一覧!$B$6:$B$492,D12) -> 31 | F12: =COUNTIFS(TODO一覧!$B$6:$B$492,D12,TODO一覧!$H$6:$H$492,"完了") -> 0 | G12: =IF(E12=0,0,F12/E12) -> 0
D13: F7 量産 | E13: =COUNTIF(TODO一覧!$B$6:$B$492,D13) -> 61 | F13: =COUNTIFS(TODO一覧!$B$6:$B$492,D13,TODO一覧!$H$6:$H$492,"完了") -> 0 | G13: =IF(E13=0,0,F13/E13) -> 0
D14: F8 コンテンツ | E14: =COUNTIF(TODO一覧!$B$6:$B$492,D14) -> 37 | F14: =COUNTIFS(TODO一覧!$B$6:$B$492,D14,TODO一覧!$H$6:$H$492,"完了") -> 0 | G14: =IF(E14=0,0,F14/E14) -> 0
D15: F9 調整 | E15: =COUNTIF(TODO一覧!$B$6:$B$492,D15) -> 54 | F15: =COUNTIFS(TODO一覧!$B$6:$B$492,D15,TODO一覧!$H$6:$H$492,"完了") -> 0 | G15: =IF(E15=0,0,F15/E15) -> 0
D16: F10 仕上げ | E16: =COUNTIF(TODO一覧!$B$6:$B$492,D16) -> 33 | F16: =COUNTIFS(TODO一覧!$B$6:$B$492,D16,TODO一覧!$H$6:$H$492,"完了") -> 0 | G16: =IF(E16=0,0,F16/E16) -> 0

Sheet TODO一覧
A2: ダンジョンゲーム 完全TODO一覧
A3: 状態・優先度・予定日・進捗・実績時間を更新すると、ダッシュボードへ反映されます。
A5: ID | B5: フェーズ | C5: 大分類 | D5: 中分類 | E5: TODO | F5: 完了条件 | G5: 優先度 | H5: 状態 | I5: 担当 | J5: 前提・依存 | K5: 開始目安 | L5: 期限 | M5: 見積h | N5: 実績h | O5: 進捗% | P5: スコープ | Q5: 主なリスク | R5: 備考
A6: T001 | B6: F0 企画固定 | C6: 企画・管理 | D6: ゲームの柱 | E6: コアループを固定する | F6: 探索→宝取得→帰還→換金→購入→再出発の流れが仕様書に明記されている | G6: P0 | H6: 完了 | I6: 自分 | K6: 46283 | L6: 46289 | M6: 1 | O6: 1 | P6: 必須
A7: T002 | B7: F0 企画固定 | C7: 企画・管理 | D7: ゲームの柱 | E7: 最終目標を10層ボス撃破に固定する | F7: 10層クリアをキャンペーンの勝利条件として明記する | G7: P0 | H7: 完了 | I7: 自分 | K7: 46283 | L7: 46289 | M7: 0.5 | O7: 1 | P7: 必須
A8: T003 | B8: F0 企画固定 | C8: 企画・管理 | D8: ゲームの柱 | E8: 遠征回数を5回に固定する | F8: 残り遠征回数の減少条件と0回時の敗北条件を明記する | G8: P0 | H8: 完了 | I8: 自分 | K8: 46283 | L8: 46289 | M8: 0.5 | O8: 1 | P8: 必須
A9: T004 | B9: F0 企画固定 | C9: 企画・管理 | D9: ゲームの柱 | E9: 5層を唯一のチェックポイントに固定する | F9: 5層到達後の開始地点選択ルールを明記する | G9: P0 | H9: 完了 | I9: 自分 | K9: 46283 | L9: 46289 | M9: 0.5 | O9: 1 | P9: 必須
A10: T005 | B10: F0 企画固定 | C10: 企画・管理 | D10: ゲームの柱 | E10: 1人用2Dゲームとして固定する | F10: 人数・画面方式・対応プラットフォームを企画書に記載する | G10: P0 | H10: 完了 | I10: 自分 | K10: 46283 | L10: 46289 | M10: 0.5 | O10: 1 | P10: 必須
A11: T006 | B11: F0 企画固定 | C11: 企画・管理 | D11: ゲームの柱 | E11: セミランダム構成を採用する | F11: 手作り部屋を抽選して並べる方式を仕様書に記載する | G11: P0 | H11: 完了 | I11: 自分 | K11: 46283 | L11: 46289 | M11: 0.5 | O11: 1 | P11: 必須
A12: T007 | B12: F0 企画固定 | C12: 企画・管理 | D12: ゲームの柱 | E12: アタッシュケースを中核システムに固定する | F12: 装備と宝が同じ容量を奪い合うルールを明記する | G12: P0 | H12: 完了 | I12: 自分 | K12: 46283 | L12: 46289 | M12: 1 | O12: 1 | P12: 必須
A13: T008 | B13: F0 企画固定 | C13: 企画・管理 | D13: 未決仕様 | E13: 戦闘方式を最終決定する | F13: 見下ろしリアルタイム戦闘の操作図と攻撃仕様が1ページで説明できる | G13: P0 | H13: 確認待ち | I13: 自分 | J13: コアループ固定 | K13: 46283 | L13: 46303 | M13: 3 | O13: 0 | P13: 必須
A14: T009 | B14: F0 企画固定 | C14: 企画・管理 | D14: 未決仕様 | E14: 対応入力機器を決める | F14: キーボード・ゲームパッドの必須対応範囲が確定している | G14: P0 | H14: 確認待ち | I14: 自分 | K14: 46283 | L14: 46303 | M14: 1 | O14: 0 | P14: 必須
A15: T010 | B15: F0 企画固定 | C15: 企画・管理 | D15: 未決仕様 | E15: 基本操作キーを決める | F15: 移動・攻撃・回避・使用・ケース・メニューの割当表がある | G15: P0 | H15: 確認待ち | I15: 自分 | J15: 対応入力機器 | K15: 46283 | L15: 46303 | M15: 1 | O15: 0 | P15: 必須
A16: T011 | B16: F0 企画固定 | C16: 企画・管理 | D16: 未決仕様 | E16: 1遠征の目標時間を決める | F16: 目標・上限・最低のプレイ時間が数値で定義されている | G16: P0 | H16: 確認待ち | I16: 自分 | K16: 46283 | L16: 46303 | M16: 1 | O16: 0 | P16: 必須
A17: T012 | B17: F0 企画固定 | C17: 企画・管理 | D17: 未決仕様 | E17: ケースの初期サイズを決める | F17: 縦横グリッド数と拡張有無が確定している | G17: P0 | H17: 確認待ち | I17: 自分 | J17: アタッシュケース固定 | K17: 46283 | L17: 46303 | M17: 2 | O17: 0 | P17: 必須
A18: T013 | B18: F0 企画固定 | C18: 企画・管理 | D18: 未決仕様 | E18: 武器の同時装備数を決める | F18: ケース内所持と即時使用のルールが確定している | G18: P0 | H18: 確認待ち | I18: 自分 | J18: 戦闘方式 | K18: 46283 | L18: 46303 | M18: 1 | O18: 0 | P18: 必須
A19: T014 | B19: F0 企画固定 | C19: 企画・管理 | D19: 未決仕様 | E19: 回復・消耗品の使用方法を決める | F19: ショートカットかメニュー停止かが確定している | G19: P0 | H19: 確認待ち | I19: 自分 | K19: 46283 | L19: 46303 | M19: 1 | O19: 0 | P19: 必須
A20: T015 | B20: F0 企画固定 | C20: 企画・管理 | D20: 未決仕様 | E20: 死亡時の所持品処理を決める | F20: 宝・装備・所持金の喪失範囲が明記されている | G20: P0 | H20: 確認待ち | I20: 自分 | K20: 46283 | L20: 46303 | M20: 2 | O20: 0 | P20: 必須
A21: T016 | B21: F0 企画固定 | C21: 企画・管理 | D21: 未決仕様 | E21: 途中帰還の方法を決める | F21: 帰還地点・帰還アイテム・任意撤退の条件が確定している | G21: P0 | H21: 確認待ち | I21: 自分 | K21: 46283 | L21: 46303 | M21: 2 | O21: 0 | P21: 必須
A22: T017 | B22: F0 企画固定 | C22: 企画・管理 | D22: 未決仕様 | E22: 5層開始時の代償を決める | F22: 1層開始との報酬・危険差が数値で説明できる | G22: P0 | H22: 確認待ち | I22: 自分 | J22: 5層チェックポイント | K22: 46283 | L22: 46303 | M22: 2 | O22: 0 | P22: 必須
A23: T018 | B23: F0 企画固定 | C23: 企画・管理 | D23: 未決仕様 | E23: ショップ在庫更新ルールを決める | F23: 更新タイミング・枠数・重複可否が確定している | G23: P0 | H23: 確認待ち | I23: 自分 | K23: 46283 | L23: 46303 | M23: 2 | O23: 0 | P23: 必須
A24: T019 | B24: F0 企画固定 | C24: 企画・管理 | D24: 未決仕様 | E24: 宝の換金タイミングを決める | F24: 自動換金・選択売却・保管のいずれかが確定している | G24: P0 | H24: 確認待ち | I24: 自分 | K24: 46283 | L24: 46303 | M24: 1 | O24: 0 | P24: 必須
A25: T020 | B25: F0 企画固定 | C25: 企画・管理 | D25: 未決仕様 | E25: セーブ仕様を決める | F25: 保存地点・保存対象・データ破損時の扱いが確定している | G25: P0 | H25: 確認待ち | I25: 自分 | K25: 46283 | L25: 46303 | M25: 2 | O25: 0 | P25: 必須
A26: T021 | B26: F0 企画固定 | C26: 企画・管理 | D26: 未決仕様 | E26: 難易度選択の有無を決める | F26: 実装するかしないかを工数込みで決定する | G26: P0 | H26: 確認待ち | I26: 自分 | K26: 46283 | L26: 46303 | M26: 1 | O26: 0 | P26: 余裕があれば
A27: T022 | B27: F0 企画固定 | C27: 企画・管理 | D27: 未決仕様 | E27: 一時停止中のゲーム挙動を決める | F27: 敵・弾・タイマーが停止する範囲を明記する | G27: P0 | H27: 確認待ち | I27: 自分 | K27: 46283 | L27: 46303 | M27: 1 | O27: 0 | P27: 必須
A28: T023 | B28: F0 企画固定 | C28: 企画・管理 | D28: 制作計画 | E28: 提出日と中間発表日を登録する | F28: 学校の正式日程がカレンダーと本表に反映されている | G28: P0 | H28: 未着手 | I28: 自分 | K28: 46283 | L28: 46295 | M28: 1 | O28: 0 | P28: 必須
A29: T024 | B29: F0 企画固定 | C29: 企画・管理 | D29: 制作計画 | E29: 週あたり制作可能時間を算出する | F29: 授業・生活を除いた実作業時間が週単位で入力されている | G29: P0 | H29: 未着手 | I29: 自分 | K29: 46283 | L29: 46295 | M29: 1 | O29: 0 | P29: 必須
A30: T025 | B30: F0 企画固定 | C30: 企画・管理 | D30: 制作計画 | E30: 必須・目標・余裕があればを分類する | F30: 全TODOのスコープ列が空欄なしになっている | G30: P0 | H30: 未着手 | I30: 自分 | K30: 46283 | L30: 46295 | M30: 2 | O30: 0 | P30: 必須
A31: T026 | B31: F0 企画固定 | C31: 企画・管理 | D31: 制作計画 | E31: 週次レビュー曜日を固定する | F31: 毎週の進捗更新時間が予定に確保されている | G31: P0 | H31: 未着手 | I31: 自分 | K31: 46283 | L31: 46295 | M31: 0.5 | O31: 0 | P31: 必須
A32: T027 | B32: F0 企画固定 | C32: 企画・管理 | D32: 制作計画 | E32: 新機能追加禁止日を設定する | F32: 2027-03-01以降は原則新機能禁止と明記されている | G32: P0 | H32: 未着手 | I32: 自分 | K32: 46283 | L32: 46295 | M32: 0.5 | O32: 0 | P32: 必須
A33: T028 | B33: F0 企画固定 | C33: 企画・管理 | D33: 制作計画 | E33: バックアップ方針を決める | F33: 日次・週次・提出前の保存先と復元手順がある | G33: P0 | H33: 未着手 | I33: 自分 | K33: 46283 | L33: 46295 | M33: 1 | O33: 0 | P33: 必須
A34: T029 | B34: F0 企画固定 | C34: 企画・管理 | D34: 制作計画 | E34: 変更履歴の書式を決める | F34: 日付・変更内容・理由・影響範囲を記録できる | G34: P0 | H34: 未着手 | I34: 自分 | K34: 46283 | L34: 46295 | M34: 1 | O34: 0 | P34: 必須
... A44: T039 | B44: F1 基礎 | C44: 開発基盤 | D44: 環境・構成 | E44: Gitリポジトリを初期化する | F44: 初回コミットと除外設定が完了している | G44: P0 | H44: 未着手 | I44: 自分 | K44: 46290 | L44: 46303 | M44: 1 | O44: 0 | P44: 必須
A45: T040 | B45: F1 基礎 | C45: 開発基盤 | D45: 環境・構成 | E45: .gitignoreを整備する | F45: ビルド生成物・個人設定・巨大一時ファイルが除外されている | G45: P0 | H45: 未着手 | I45: 自分 | J45: Git初期化 | K45: 46290 | L45: 46303 | M45: 1 | O45: 0 | P45: 必須
A46: T041 | B46: F1 基礎 | C46: 開発基盤 | D46: 環境・構成 | E46: ブランチ運用を決める | F46: mainと作業ブランチの使用ルールが1ページで確認できる | G46: P0 | H46: 未着手 | I46: 自分 | J46: Git初期化 | K46: 46290 | L46: 46303 | M46: 1 | O46: 0 | P46: 必須
A47: T042 | B47: F1 基礎 | C47: 開発基盤 | D47: 環境・構成 | E47: クラッシュログ保存先を作る | F47: 例外・アサート・直前シーンを記録できる | G47: P0 | H47: 未着手 | I47: 自分 | K47: 46290 | L47: 46303 | M47: 3 | O47: 0 | P47: 必須
A48: T043 | B48: F1 基礎 | C48: 開発基盤 | D48: 環境・構成 | E48: ログ出力機能を作る | F48: INFO・WARN・ERRORをファイルとデバッグ出力へ出せる | G48: P0 | H48: 未着手 | I48: 自分 | K48: 46290 | L48: 46303 | M48: 3 | O48: 0 | P48: 必須
A49: T044 | B49: F1 基礎 | C49: 開発基盤 | D49: 環境・構成 | E49: アサート方針を整える | F49: 不正データをDebugで即検出できる | G49: P0 | H49: 未着手 | I49: 自分 | K49: 46290 | L49: 46303 | M49: 2 | O49: 0 | P49: 必須
A50: T045 | B50: F1 基礎 | C50: 開発基盤 | D50: 環境・構成 | E50: フレーム時間計測を作る | F50: FPSと1フレーム時間を画面またはログで確認できる | G50: P0 | H50: 未着手 | I50: 自分 | K50: 46290 | L50: 46303 | M50: 2 | O50: 0 | P50: 必須
A51: T046 | B51: F1 基礎 | C51: 開発基盤 | D51: 環境・構成 | E51: ウィンドウ設定を作る | F51: 解像度・フルスクリーン・タイトルを設定から変更できる | G51: P0 | H51: 未着手 | I51: 自分 | K51: 46290 | L51: 46303 | M51: 3 | O51: 0 | P51: 必須
...

Sheet 仕様確定
A2: 仕様確定リスト
A3: 未決定・要判断を期限までに0件へ。決定変更時はTODO・データ・テストへ影響を反映してください。
A5: ID | B5: 分野 | C5: 項目 | D5: 現在案 | E5: 状態 | F5: 影響範囲 | G5: 確定期限 | H5: 次アクション
A6: S001 | B6: 基本 | C6: プレイ人数 | D6: 1人 | E6: 確定 | F6: 全体 | H6: 企画書へ反映
A7: S002 | B7: 基本 | C7: プラットフォーム | D7: Windows PC | E7: 確定 | F7: 開発・提出 | H7: 対象OS版を明記
A8: S003 | B8: 基本 | C8: 開発環境 | D8: Visual Studio 2026 / C++ / 学校ライブラリ | E8: 確定 | F8: 全体 | H8: vividは原則変更しない
A9: S004 | B9: 基本 | C9: 視点 | D9: 2D見下ろし | E9: 仮確定 | F9: 戦闘・素材 | G9: 46303 | H9: 戦闘試作前に固定
A10: S005 | B10: 戦闘 | C10: 戦闘方式 | D10: リアルタイム | E10: 仮確定 | F10: 戦闘全体 | G10: 46303 | H10: 操作図を作る
A11: S006 | B11: 戦闘 | C11: 通常攻撃 | D11: 未決定 | E11: 未決定 | F11: 武器・入力 | G11: 46303 | H11: 入力と判定方式
A12: S007 | B12: 戦闘 | C12: 回避 | D12: 未決定 | E12: 未決定 | F12: 操作感 | G12: 46303 | H12: 無敵・距離・硬直
A13: S008 | B13: 戦闘 | C13: 遠距離武器 | D13: 最低1種を候補 | E13: 要判断 | F13: 工数 | G13: 46310 | H13: 目標スコープ
A14: S009 | B14: 戦闘 | C14: クリティカル | D14: 未決定 | E14: 要判断 | F14: 数値調整 | G14: 46310 | H14: なくても成立
A15: S010 | B15: 進行 | C15: 最終層 | D15: 10層 | E15: 確定 | F15: キャンペーン | H15: 10層はボス
A16: S011 | B16: 進行 | C16: 遠征回数 | D16: 5回 | E16: 確定 | F16: キャンペーン | H16: 消費タイミング要確定
A17: S012 | B17: 進行 | C17: チェックポイント | D17: 5層のみ | E17: 確定 | F17: 開始層 | H17: 到達後に解放
A18: S013 | B18: 進行 | C18: 開始層選択 | D18: 1層/5層 | E18: 確定 | F18: UI・バランス | H18: 5層到達後のみ
A19: S014 | B19: 進行 | C19: 5層開始の代償 | D19: 未決定 | E19: 未決定 | F19: バランス | G19: 46356 | H19: 報酬・初期装備・危険差
A20: S015 | B20: 進行 | C20: 死亡時損失 | D20: 未決定 | E20: 未決定 | F20: ループ・セーブ | G20: 46315 | H20: 宝・装備・通貨
A21: S016 | B21: 進行 | C21: 途中帰還 | D21: 採用予定 | E21: 仮確定 | F21: コアループ | G21: 46315 | H21: 手段と場所を決める
A22: S017 | B22: 時間 | C22: 1遠征時間 | D22: 未決定 | E22: 未決定 | F22: 全体工数・調整 | G22: 46303 | H22: 目標/上限/最低
A23: S018 | B23: 時間 | C23: 1キャンペーン時間 | D23: 未決定 | E23: 未決定 | F23: 全体バランス | G23: 46387 | H23: 実測から固定
A24: S019 | B24: ケース | C24: ケース方式 | D24: グリッド配置 | E24: 確定 | F24: 中核 | H24: 回転あり
A25: S020 | B25: ケース | C25: 対象 | D25: 武器・消耗品・宝 | E25: 確定 | F25: 中核 | H25: 同じ空間を使用
A26: S021 | B26: ケース | C26: 初期サイズ | D26: 未決定 | E26: 未決定 | F26: 全アイテム | G26: 46303 | H26: 縦×横
A27: S022 | B27: ケース | C27: アイテム形状 | D27: 矩形/マスク未決定 | E27: 要判断 | F27: 実装量 | G27: 46315 | H27: 最小は矩形
A28: S023 | B28: ケース | C28: スタック | D28: 消耗品のみ候補 | E28: 要判断 | F28: UI・保存 | G28: 46315 | H28: 上限数も決定
A29: S024 | B29: ショップ | C29: 在庫ランダム | D29: 採用 | E29: 確定 | F29: 経済 | H29: 更新ルールは未決
A30: S025 | B30: ショップ | C30: 在庫枠数 | D30: 未決定 | E30: 未決定 | F30: 経済・UI | G30: 46346 | H30: 最低保証含む
A31: S026 | B31: ショップ | C31: 装備売却 | D31: 未決定 | E31: 要判断 | F31: 経済 | G31: 46351 | H31: 必須ではない
A32: S027 | B32: 宝 | C32: 出現ランダム | D32: 採用 | E32: 確定 | F32: 探索 | H32: 層別重み
A33: S028 | B33: 宝 | C33: 換金 | D33: 帰還時 | E33: 仮確定 | F33: 経済 | G33: 46315 | H33: 自動/選択を決定
A34: S029 | B34: 宝 | C34: レア度 | D34: 未決定 | E34: 未決定 | F34: 演出・価格 | G34: 46346 | H34: 3段階を候補
A35: S030 | B35: ステージ | C35: 生成方式 | D35: 手作り部屋のセミランダム | E35: 確定 | F35: ステージ | H35: 完全自動生成ではない
A36: S031 | B36: ステージ | C36: 前半候補数 | D36: 最終10、制作順3→5→10 | E36: 暫定 | F36: 工数 | G36: 46409 | H36: 最低3
A37: S032 | B37: ステージ | C37: 後半候補数 | D37: 最終10、制作順3→5→10 | E37: 暫定 | F37: 工数 | G37: 46409 | H37: 最低3
A38: S033 | B38: 敵 | C38: 敵種類数 | D38: 最低3、目標5 | E38: 暫定 | F38: 素材・AI | G38: 46402 | H38: 役割差を優先
A39: S034 | B39: 武器 | C39: 武器種類数 | D39: 最低3、目標4、上限5 | E39: 暫定 | F39: 素材・調整 | G39: 46402 | H39: 役割差を優先
A40: S035 | B40: ボス | C40: 形態数 | D40: 最低1、追加形態は目標 | E40: 暫定 | F40: 工数 | G40: 46397 | H40: 攻撃3種以上
A41: S036 | B41: セーブ | C41: 保存地点 | D41: 帰還時+設定変更時を候補 | E41: 未決定 | F41: 破損リスク | G41: 46356 | H41: 出発時も検討
A42: S037 | B42: 入力 | C42: キーボード | D42: 必須候補 | E42: 要確定 | F42: 操作 | G42: 46303 | H42: キー表作成
...

Sheet コンテンツ管理
A2: コンテンツ量と完成条件
A3: 最低を先に完成し、目標へ増やします。上限は時間に余裕がある場合のみ。
A5: ID | B5: 分類 | C5: 内容 | D5: 最低 | E5: 目標 | F5: 上限 | G5: 単位 | H5: 状態 | I5: 完成条件 | J5: 備考
A6: C001 | B6: ステージ | C6: 前半部屋 | D6: 3 | E6: 5 | F6: 10 | G6: 部屋 | H6: 未着手 | I6: 通行・戦闘・宝配置が成立 | J6: 10は最終目標
A7: C002 | B7: ステージ | C7: 後半部屋 | D7: 3 | E7: 5 | F7: 10 | G7: 部屋 | H7: 未着手 | I7: 通行・戦闘・宝配置が成立 | J7: 10は最終目標
A8: C003 | B8: ステージ | C8: 5層固定部屋 | D8: 1 | E8: 1 | F8: 1 | G8: 部屋 | H8: 未着手 | I8: CP解放と開始地点が動く | J8: 必須
A9: C004 | B9: ステージ | C9: 10層ボス部屋 | D9: 1 | E9: 1 | F9: 1 | G9: 部屋 | H9: 未着手 | I9: ボス戦とクリアが動く | J9: 必須
A10: C005 | B10: 敵 | C10: 通常敵種類 | D10: 3 | E10: 4 | F10: 5 | G10: 種 | H10: 未着手 | I10: 役割と出現帯が異なる | J10: 追加は工数次第
A11: C006 | B11: 敵 | C11: 強敵バリエーション | D11: 0 | E11: 1 | F11: 2 | G11: 種 | H11: 未着手 | I11: 後半の違いを作る | J11: 色替えだけにしない
A12: C007 | B12: ボス | C12: ボス本体 | D12: 1 | E12: 1 | F12: 1 | G12: 体 | H12: 未着手 | I12: 攻撃3種以上で撃破可能 | J12: 必須
A13: C008 | B13: 武器 | C13: 近接武器 | D13: 2 | E13: 3 | F13: 4 | G13: 種 | H13: 未着手 | I13: 速度・範囲・威力・占有が異なる | J13: 標準/高速/重量
A14: C009 | B14: 武器 | C14: 遠距離武器 | D14: 0 | E14: 1 | F14: 1 | G14: 種 | H14: 未着手 | I14: 弾制限込みで成立 | J14: 目標
A15: C010 | B15: 消耗品 | C15: 回復 | D15: 1 | E15: 2 | F15: 2 | G15: 種 | H15: 未着手 | I15: 価格・回復量・サイズ差がある | J15: 必須1
A16: C011 | B16: 消耗品 | C16: 強化・帰還 | D16: 0 | E16: 1 | F16: 2 | G16: 種 | H16: 未着手 | I16: 固有効果が正しく終了 | J16: 目標
A17: C012 | B17: 宝 | C17: 低価値宝 | D17: 3 | E17: 3 | F17: 5 | G17: 種 | H17: 未着手 | I17: 画像・価値・サイズが揃う
A18: C013 | B18: 宝 | C18: 中価値宝 | D18: 3 | E18: 3 | F18: 5 | G18: 種 | H18: 未着手 | I18: 画像・価値・サイズが揃う
A19: C014 | B19: 宝 | C19: 高価値宝 | D19: 2 | E19: 2 | F19: 3 | G19: 種 | H19: 未着手 | I19: 発見演出と判断価値がある
A20: C015 | B20: 宝 | C20: 特殊形状宝 | D20: 0 | E20: 2 | F20: 3 | G20: 種 | H20: 未着手 | I20: ケース配置に変化を作る | J20: 目標
A21: C016 | B21: UI | C21: 主要画面 | D21: 8 | E21: 8 | F21: 10 | G21: 画面 | H21: 未着手 | I21: 全画面をキーで操作可能 | J21: タイトル/拠点/HUD/ケース/ショップ/ポーズ/勝利/敗北
A22: C017 | B22: BGM | C22: 楽曲 | D22: 4 | E22: 5 | F22: 6 | G22: 曲 | H22: 未着手 | I22: ループと切替が自然 | J22: タイトル/拠点/前半/後半/ボス
A23: C018 | B23: SE | C23: カテゴリ | D23: 4 | E23: 5 | F23: 6 | G23: 群 | H23: 未着手 | I23: 主要操作に音がある | J23: プレイヤー/敵/アイテム/UI/環境
A24: C019 | B24: チュートリアル | C24: 説明単位 | D24: 3 | E24: 6 | F24: 8 | G24: 項目 | H24: 未着手 | I24: 初見が口頭説明なしで遊べる
A25: C020 | B25: 資料 | C25: README・操作表・ライセンス | D25: 3 | E25: 3 | F25: 5 | G25: 点 | H25: 未着手 | I25: 第三者が起動・操作・確認できる

Sheet リスク・提出
A2: リスク管理
A4: ID | B4: 分類 | C4: リスク | D4: 影響 | E4: 確率 | F4: スコア | G4: 予防 | H4: 発生時対応 | I4: 状態
A5: R01 | B5: 仕様 | C5: 戦闘仕様が決まらず前半工程が止まる | D5: 5 | E5: 5 | F5: 25 | G5: 2026-10-08までに武器1種の操作を固定 | H5: 武器種類と演出を削減 | I5: 未対応
A6: R02 | B6: 規模 | C6: 部屋20種の量産が終わらない | D6: 5 | E6: 4 | F6: 20 | G6: 3+3→5+5→10+10の順で完成させる | H6: 最低3+3で提出 | I6: 未対応
A7: R03 | B7: 規模 | C7: 武器・敵を増やしすぎる | D7: 4 | E7: 4 | F7: 16 | G7: 役割表で最低数を先に固定 | H7: 追加分を削る | I7: 未対応
A8: R04 | B8: 中核 | C8: ケースUIが操作しづらい | D8: 5 | E8: 4 | F8: 20 | G8: 11月中に仮素材で操作テスト | H8: 形状を矩形へ簡略化 | I8: 未対応
A9: R05 | B9: 技術 | C9: セーブ破損で進行を失う | D9: 5 | E9: 3 | F9: 15 | G9: 一時ファイルと1世代バックアップ | H9: 初期化案内と復元 | I9: 未対応
A10: R06 | B10: 技術 | C10: セミランダムで進行不能が出る | D10: 5 | E10: 3 | F10: 15 | G10: 候補点・到達検査・固定シードログ | H10: 不正部屋を抽選対象外 | I10: 未対応
A11: R07 | B11: 品質 | C11: 低FPSで当たり判定が抜ける | D11: 4 | E11: 3 | F11: 12 | G11: 時間依存処理と負荷試験 | H11: 敵・弾上限を下げる | I11: 未対応
A12: R08 | B12: 設計 | C12: 5層開始が常に最適になる | D12: 4 | E12: 4 | F12: 16 | G12: 期待収益と装備差を測る | H12: 5層開始の条件を調整 | I12: 未対応
A13: R09 | B13: 設計 | C13: 帰還せず進むだけが最適になる | D13: 5 | E13: 4 | F13: 20 | G13: 死亡損失と宝価値をテスト | H13: 後半危険度と帰還利益を調整 | I13: 未対応
A14: R10 | B14: 設計 | C14: ケースで選択が発生しない | D14: 5 | E14: 4 | F14: 20 | G14: 宝サイズと装備占有を計測 | H14: ケース縮小または大型宝追加 | I14: 未対応
A15: R11 | B15: 制作 | C15: 本素材待ちで実装が止まる | D15: 4 | E15: 4 | F15: 16 | G15: 仮素材で全機能を先行完成 | H15: 本素材を最低限に絞る | I15: 未対応
A16: R12 | B16: 制作 | C16: 音源・素材の権利が不明 | D16: 5 | E16: 2 | F16: 10 | G16: 取得時にライセンス記録 | H16: 該当素材を自作/差替え | I16: 未対応
... A22: R18 | B22: 性能 | C22: エフェクト過多で処理落ち | D22: 3 | E22: 3 | F22: 9 | G22: 同時数上限とプールを採用 | H22: 品質設定または表示削減 | I22: 未対応
A26: 最終提出チェックリスト
A27: ID | B27: 確認項目 | C27: 優先度 | D27: 状態 | E27: 合格条件
A28: RC01 | B28: Releaseビルド成功 | C28: P0 | D28: 未確認 | E28: ビルドログにエラー0
A29: RC02 | B29: 別PC起動成功 | C29: P0 | D29: 未確認 | E29: タイトルから1遠征完了
A30: RC03 | B30: 提出ZIP再展開成功 | C30: P0 | D30: 未確認 | E30: 任意フォルダから起動
A31: RC04 | B31: 初期セーブ状態 | C31: P0 | D31: 未確認 | E31: 個人データなし
A32: RC05 | B32: 操作説明一致 | C32: P0 | D32: 未確認 | E32: 全キー/ボタンが実装と一致
A33: RC06 | B33: README完成 | C33: P0 | D33: 未確認 | E33: 起動・ルール・既知問題を記載
A34: RC07 | B34: ライセンス確認 | C34: P0 | D34: 未確認 | E34: 表記漏れ・禁止素材0
A35: RC08 | B35: 重大バグ0件 | C35: P0 | D35: 未確認 | E35: クラッシュ・進行不能・データ消失0
A36: RC09 | B36: 既知不具合記載 | C36: P1 | D36: 未確認 | E36: 再現条件と回避方法を記載
A37: RC10 | B37: 最終バックアップ | C37: P0 | D37: 未確認 | E37: ソース・素材・提出ZIPを別保存
A38: RC11 | B38: ハッシュ記録 | C38: P1 | D38: 未確認 | E38: 提出ファイルと記録が一致
A39: RC12 | B39: 提出証跡保存 | C39: P0 | D39: 未確認 | E39: 受付画面・日時・ファイル名を保存

Sheet 使い方
A2: このExcelの使い方
A4: 更新する場所 | B4: 方法
A5: TODO一覧 / 状態 | B5: 未着手・進行中・確認待ち・保留・完了から選択
A6: TODO一覧 / 進捗% | B6: 0〜100%を入力。見積時間で重み付けして全体進捗を計算
A7: TODO一覧 / 実績h | B7: 作業後に実際の時間を入力
A8: 仕様確定 / 状態 | B8: 未決定と要判断を期限までに解消
A9: コンテンツ管理 | B9: 最低を先に完成し、目標・上限は余力で追加
A10: テスト計画 | B10: 不合格時は不具合IDと再現条件をメモ
A11: リスク管理 | B11: 週次レビューで高スコアから予防策を実施
A12: リスク・提出 | B12: 提出前に全項目を合格へ変更
A14: 運用ルール | B14: 内容
A15: 毎日 | B15: 作業したTODOの状態・進捗・実績時間を更新
A16: 毎週 | B16: 翌週のP0を5件以内に絞り、期限遅延を確認
... A29: 更新基準日 | B29: 2026-09-18
